<?xml version="1.0" encoding="utf-8"?>
<!-- =================================================================================== -->
<!-- |    This document was autogenerated by xacro from /home/ou/workspace/ros_ws/src/tricycle/urdf/tricycle.xacro | -->
<!-- |    EDITING THIS FILE BY HAND IS NOT RECOMMENDED                                 | -->
<!-- =================================================================================== -->
<robot name="tricycle">
  <link name="base_link">
    <inertial>
      <origin rpy="0 0 0" xyz="0 0 0.02"/>
      <mass value="0.5"/>
      <inertia ixx="0.000420833165" ixy="0.0" ixz="0.0" iyy="0.000420833165" iyz="0.0" izz="0.000833333"/>
    </inertial>
    <visual>
      <origin rpy="0 0 0" xyz="0 0 0.02"/>
      <geometry>
        <box size="0.1 0.1 0.01"/>
      </geometry>
    </visual>
    <collision>
      <origin rpy="0 0 0" xyz="0 0 0.02"/>
      <geometry>
        <box size="0.1 0.1 0.01"/>
      </geometry>
    </collision>
  </link>
  <!-- for base_wheel joint -->
  <joint name="base_wheel_0_joint" type="continuous">
    <origin rpy="1.57079632679 0 1.57079632679" xyz="0.0707106781187 0.0 -0.01"/>
    <axis xyz="0 0 1"/>
    <parent link="base_link"/>
    <child link="wheel_0"/>
    <dynamics damping="0.01" friction="0.1"/>
  </joint>
  <link name="wheel_0">
    <inertial>
      <origin rpy="0 0 0" xyz="0 0 0"/>
      <mass value="0.1"/>
      <!-- [kg] -->
      <inertia ixx="0.0000005" ixy="0.0" ixz="0.0" iyy="0.0000005" iyz="0.0" izz="0.0000007"/>
      <!-- [kg m^2] [kg m^2] [kg m^2] [kg m^2] [kg m^2] [kg m^2] -->
    </inertial>
    <visual>
      <origin rpy="0 0 0" xyz="0 0 0"/>
      <origin rpy="1.57079632679 0 1.57079632679" xyz="0.0707106781187 0.0 -0.01"/>
      <geometry>
        <mesh filename="/home/ou/workspace/ros_ws/src/tricycle/meshes/wheel_frame.stl" scale="1 1 1"/>
      </geometry>
    </visual>
    <collision>
      <origin rpy="0 0 0" xyz="0 0 0"/>
      <geometry>
        <mesh filename="/home/ou/workspace/ros_ws/src/tricycle/meshes/wheel_frame.stl" scale="1 1 1"/>
      </geometry>
    </collision>
  </link>
  <!-- for bar link -->
  <link name="wheel_0/bar_0">
    <inertial>
      <origin rpy="0 0 0" xyz="0 0 0"/>
      <mass value="0.005"/>
      <!--                <xacro:cylinder_inertia r="0.001" l="0.003" mass="${wheel_bar_mass}"/>-->
      <inertia ixx="0.000000026" ixy="0.0" ixz="0.0" iyy="0.000000026" iyz="0.0" izz="0.000000018"/>
    </inertial>
    <visual>
      <origin rpy="0 0 0" xyz="0 0 0"/>
      <geometry>
        <mesh filename="/home/ou/workspace/ros_ws/src/tricycle/meshes/bar.stl" scale="1.0 1.0 1.0"/>
      </geometry>
    </visual>
    <collision>
      <origin rpy="0 0 0" xyz="0 0 0"/>
      <geometry>
        <mesh filename="/home/ou/workspace/ros_ws/src/tricycle/meshes/bar.stl" scale="1.0 1.0 1.0"/>
      </geometry>
    </collision>
  </link>
  <joint name="wheel_0/bar_joint_0" type="continuous">
    <origin rpy="1.57079632679 0 0.0" xyz="0.02 0.0 0.02098"/>
    <axis xyz="0 0 1"/>
    <parent link="wheel_0"/>
    <child link="wheel_0/bar_0"/>
  </joint>
  <gazebo reference="wheel_0/bar_0">
    <mu1>0.5</mu1>
    <mu2>0.5</mu2>
    <material>Gazebo/Black</material>
    <gravity>true</gravity>
    <minDepth>0.0005 </minDepth>
  </gazebo>
  <!-- for bar link -->
  <link name="wheel_0/bar_6">
    <inertial>
      <origin rpy="0 0 0" xyz="0 0 0"/>
      <mass value="0.005"/>
      <!--                <xacro:cylinder_inertia r="0.001" l="0.003" mass="${wheel_bar_mass}"/>-->
      <inertia ixx="0.000000026" ixy="0.0" ixz="0.0" iyy="0.000000026" iyz="0.0" izz="0.000000018"/>
    </inertial>
    <visual>
      <origin rpy="0 0 0" xyz="0 0 0"/>
      <geometry>
        <mesh filename="/home/ou/workspace/ros_ws/src/tricycle/meshes/bar.stl" scale="1.0 1.0 1.0"/>
      </geometry>
    </visual>
    <collision>
      <origin rpy="0 0 0" xyz="0 0 0"/>
      <geometry>
        <mesh filename="/home/ou/workspace/ros_ws/src/tricycle/meshes/bar.stl" scale="1.0 1.0 1.0"/>
      </geometry>
    </collision>
  </link>
  <joint name="wheel_0/bar_joint_6" type="continuous">
    <origin rpy="1.57079632679 0 0.523598775598" xyz="0.0173205080757 0.01 0.01028"/>
    <axis xyz="0 0 1"/>
    <parent link="wheel_0"/>
    <child link="wheel_0/bar_6"/>
  </joint>
  <gazebo reference="wheel_0/bar_6">
    <mu1>0.5</mu1>
    <mu2>0.5</mu2>
    <material>Gazebo/Black</material>
    <gravity>true</gravity>
    <minDepth>0.0005 </minDepth>
  </gazebo>
  <!-- for bar link -->
  <link name="wheel_0/bar_1">
    <inertial>
      <origin rpy="0 0 0" xyz="0 0 0"/>
      <mass value="0.005"/>
      <!--                <xacro:cylinder_inertia r="0.001" l="0.003" mass="${wheel_bar_mass}"/>-->
      <inertia ixx="0.000000026" ixy="0.0" ixz="0.0" iyy="0.000000026" iyz="0.0" izz="0.000000018"/>
    </inertial>
    <visual>
      <origin rpy="0 0 0" xyz="0 0 0"/>
      <geometry>
        <mesh filename="/home/ou/workspace/ros_ws/src/tricycle/meshes/bar.stl" scale="1.0 1.0 1.0"/>
      </geometry>
    </visual>
    <collision>
      <origin rpy="0 0 0" xyz="0 0 0"/>
      <geometry>
        <mesh filename="/home/ou/workspace/ros_ws/src/tricycle/meshes/bar.stl" scale="1.0 1.0 1.0"/>
      </geometry>
    </collision>
  </link>
  <joint name="wheel_0/bar_joint_1" type="continuous">
    <origin rpy="1.57079632679 0 1.0471975512" xyz="0.01 0.0173205080757 0.02098"/>
    <axis xyz="0 0 1"/>
    <parent link="wheel_0"/>
    <child link="wheel_0/bar_1"/>
  </joint>
  <gazebo reference="wheel_0/bar_1">
    <mu1>0.5</mu1>
    <mu2>0.5</mu2>
    <material>Gazebo/Black</material>
    <gravity>true</gravity>
    <minDepth>0.0005 </minDepth>
  </gazebo>
  <!-- for bar link -->
  <link name="wheel_0/bar_7">
    <inertial>
      <origin rpy="0 0 0" xyz="0 0 0"/>
      <mass value="0.005"/>
      <!--                <xacro:cylinder_inertia r="0.001" l="0.003" mass="${wheel_bar_mass}"/>-->
      <inertia ixx="0.000000026" ixy="0.0" ixz="0.0" iyy="0.000000026" iyz="0.0" izz="0.000000018"/>
    </inertial>
    <visual>
      <origin rpy="0 0 0" xyz="0 0 0"/>
      <geometry>
        <mesh filename="/home/ou/workspace/ros_ws/src/tricycle/meshes/bar.stl" scale="1.0 1.0 1.0"/>
      </geometry>
    </visual>
    <collision>
      <origin rpy="0 0 0" xyz="0 0 0"/>
      <geometry>
        <mesh filename="/home/ou/workspace/ros_ws/src/tricycle/meshes/bar.stl" scale="1.0 1.0 1.0"/>
      </geometry>
    </collision>
  </link>
  <joint name="wheel_0/bar_joint_7" type="continuous">
    <origin rpy="1.57079632679 0 1.57079632679" xyz="1.22464679915e-18 0.02 0.01028"/>
    <axis xyz="0 0 1"/>
    <parent link="wheel_0"/>
    <child link="wheel_0/bar_7"/>
  </joint>
  <gazebo reference="wheel_0/bar_7">
    <mu1>0.5</mu1>
    <mu2>0.5</mu2>
    <material>Gazebo/Black</material>
    <gravity>true</gravity>
    <minDepth>0.0005 </minDepth>
  </gazebo>
  <!-- for bar link -->
  <link name="wheel_0/bar_2">
    <inertial>
      <origin rpy="0 0 0" xyz="0 0 0"/>
      <mass value="0.005"/>
      <!--                <xacro:cylinder_inertia r="0.001" l="0.003" mass="${wheel_bar_mass}"/>-->
      <inertia ixx="0.000000026" ixy="0.0" ixz="0.0" iyy="0.000000026" iyz="0.0" izz="0.000000018"/>
    </inertial>
    <visual>
      <origin rpy="0 0 0" xyz="0 0 0"/>
      <geometry>
        <mesh filename="/home/ou/workspace/ros_ws/src/tricycle/meshes/bar.stl" scale="1.0 1.0 1.0"/>
      </geometry>
    </visual>
    <collision>
      <origin rpy="0 0 0" xyz="0 0 0"/>
      <geometry>
        <mesh filename="/home/ou/workspace/ros_ws/src/tricycle/meshes/bar.stl" scale="1.0 1.0 1.0"/>
      </geometry>
    </collision>
  </link>
  <joint name="wheel_0/bar_joint_2" type="continuous">
    <origin rpy="1.57079632679 0 2.09439510239" xyz="-0.01 0.0173205080757 0.02098"/>
    <axis xyz="0 0 1"/>
    <parent link="wheel_0"/>
    <child link="wheel_0/bar_2"/>
  </joint>
  <gazebo reference="wheel_0/bar_2">
    <mu1>0.5</mu1>
    <mu2>0.5</mu2>
    <material>Gazebo/Black</material>
    <gravity>true</gravity>
    <minDepth>0.0005 </minDepth>
  </gazebo>
  <!-- for bar link -->
  <link name="wheel_0/bar_8">
    <inertial>
      <origin rpy="0 0 0" xyz="0 0 0"/>
      <mass value="0.005"/>
      <!--                <xacro:cylinder_inertia r="0.001" l="0.003" mass="${wheel_bar_mass}"/>-->
      <inertia ixx="0.000000026" ixy="0.0" ixz="0.0" iyy="0.000000026" iyz="0.0" izz="0.000000018"/>
    </inertial>
    <visual>
      <origin rpy="0 0 0" xyz="0 0 0"/>
      <geometry>
        <mesh filename="/home/ou/workspace/ros_ws/src/tricycle/meshes/bar.stl" scale="1.0 1.0 1.0"/>
      </geometry>
    </visual>
    <collision>
      <origin rpy="0 0 0" xyz="0 0 0"/>
      <geometry>
        <mesh filename="/home/ou/workspace/ros_ws/src/tricycle/meshes/bar.stl" scale="1.0 1.0 1.0"/>
      </geometry>
    </collision>
  </link>
  <joint name="wheel_0/bar_joint_8" type="continuous">
    <origin rpy="1.57079632679 0 2.61799387799" xyz="-0.0173205080757 0.01 0.01028"/>
    <axis xyz="0 0 1"/>
    <parent link="wheel_0"/>
    <child link="wheel_0/bar_8"/>
  </joint>
  <gazebo reference="wheel_0/bar_8">
    <mu1>0.5</mu1>
    <mu2>0.5</mu2>
    <material>Gazebo/Black</material>
    <gravity>true</gravity>
    <minDepth>0.0005 </minDepth>
  </gazebo>
  <!-- for bar link -->
  <link name="wheel_0/bar_3">
    <inertial>
      <origin rpy="0 0 0" xyz="0 0 0"/>
      <mass value="0.005"/>
      <!--                <xacro:cylinder_inertia r="0.001" l="0.003" mass="${wheel_bar_mass}"/>-->
      <inertia ixx="0.000000026" ixy="0.0" ixz="0.0" iyy="0.000000026" iyz="0.0" izz="0.000000018"/>
    </inertial>
    <visual>
      <origin rpy="0 0 0" xyz="0 0 0"/>
      <geometry>
        <mesh filename="/home/ou/workspace/ros_ws/src/tricycle/meshes/bar.stl" scale="1.0 1.0 1.0"/>
      </geometry>
    </visual>
    <collision>
      <origin rpy="0 0 0" xyz="0 0 0"/>
      <geometry>
        <mesh filename="/home/ou/workspace/ros_ws/src/tricycle/meshes/bar.stl" scale="1.0 1.0 1.0"/>
      </geometry>
    </collision>
  </link>
  <joint name="wheel_0/bar_joint_3" type="continuous">
    <origin rpy="1.57079632679 0 3.14159265359" xyz="-0.02 2.44929359829e-18 0.02098"/>
    <axis xyz="0 0 1"/>
    <parent link="wheel_0"/>
    <child link="wheel_0/bar_3"/>
  </joint>
  <gazebo reference="wheel_0/bar_3">
    <mu1>0.5</mu1>
    <mu2>0.5</mu2>
    <material>Gazebo/Black</material>
    <gravity>true</gravity>
    <minDepth>0.0005 </minDepth>
  </gazebo>
  <!-- for bar link -->
  <link name="wheel_0/bar_9">
    <inertial>
      <origin rpy="0 0 0" xyz="0 0 0"/>
      <mass value="0.005"/>
      <!--                <xacro:cylinder_inertia r="0.001" l="0.003" mass="${wheel_bar_mass}"/>-->
      <inertia ixx="0.000000026" ixy="0.0" ixz="0.0" iyy="0.000000026" iyz="0.0" izz="0.000000018"/>
    </inertial>
    <visual>
      <origin rpy="0 0 0" xyz="0 0 0"/>
      <geometry>
        <mesh filename="/home/ou/workspace/ros_ws/src/tricycle/meshes/bar.stl" scale="1.0 1.0 1.0"/>
      </geometry>
    </visual>
    <collision>
      <origin rpy="0 0 0" xyz="0 0 0"/>
      <geometry>
        <mesh filename="/home/ou/workspace/ros_ws/src/tricycle/meshes/bar.stl" scale="1.0 1.0 1.0"/>
      </geometry>
    </collision>
  </link>
  <joint name="wheel_0/bar_joint_9" type="continuous">
    <origin rpy="1.57079632679 0 3.66519142919" xyz="-0.0173205080757 -0.01 0.01028"/>
    <axis xyz="0 0 1"/>
    <parent link="wheel_0"/>
    <child link="wheel_0/bar_9"/>
  </joint>
  <gazebo reference="wheel_0/bar_9">
    <mu1>0.5</mu1>
    <mu2>0.5</mu2>
    <material>Gazebo/Black</material>
    <gravity>true</gravity>
    <minDepth>0.0005 </minDepth>
  </gazebo>
  <!-- for bar link -->
  <link name="wheel_0/bar_4">
    <inertial>
      <origin rpy="0 0 0" xyz="0 0 0"/>
      <mass value="0.005"/>
      <!--                <xacro:cylinder_inertia r="0.001" l="0.003" mass="${wheel_bar_mass}"/>-->
      <inertia ixx="0.000000026" ixy="0.0" ixz="0.0" iyy="0.000000026" iyz="0.0" izz="0.000000018"/>
    </inertial>
    <visual>
      <origin rpy="0 0 0" xyz="0 0 0"/>
      <geometry>
        <mesh filename="/home/ou/workspace/ros_ws/src/tricycle/meshes/bar.stl" scale="1.0 1.0 1.0"/>
      </geometry>
    </visual>
    <collision>
      <origin rpy="0 0 0" xyz="0 0 0"/>
      <geometry>
        <mesh filename="/home/ou/workspace/ros_ws/src/tricycle/meshes/bar.stl" scale="1.0 1.0 1.0"/>
      </geometry>
    </collision>
  </link>
  <joint name="wheel_0/bar_joint_4" type="continuous">
    <origin rpy="1.57079632679 0 4.18879020479" xyz="-0.01 -0.0173205080757 0.02098"/>
    <axis xyz="0 0 1"/>
    <parent link="wheel_0"/>
    <child link="wheel_0/bar_4"/>
  </joint>
  <gazebo reference="wheel_0/bar_4">
    <mu1>0.5</mu1>
    <mu2>0.5</mu2>
    <material>Gazebo/Black</material>
    <gravity>true</gravity>
    <minDepth>0.0005 </minDepth>
  </gazebo>
  <!-- for bar link -->
  <link name="wheel_0/bar_10">
    <inertial>
      <origin rpy="0 0 0" xyz="0 0 0"/>
      <mass value="0.005"/>
      <!--                <xacro:cylinder_inertia r="0.001" l="0.003" mass="${wheel_bar_mass}"/>-->
      <inertia ixx="0.000000026" ixy="0.0" ixz="0.0" iyy="0.000000026" iyz="0.0" izz="0.000000018"/>
    </inertial>
    <visual>
      <origin rpy="0 0 0" xyz="0 0 0"/>
      <geometry>
        <mesh filename="/home/ou/workspace/ros_ws/src/tricycle/meshes/bar.stl" scale="1.0 1.0 1.0"/>
      </geometry>
    </visual>
    <collision>
      <origin rpy="0 0 0" xyz="0 0 0"/>
      <geometry>
        <mesh filename="/home/ou/workspace/ros_ws/src/tricycle/meshes/bar.stl" scale="1.0 1.0 1.0"/>
      </geometry>
    </collision>
  </link>
  <joint name="wheel_0/bar_joint_10" type="continuous">
    <origin rpy="1.57079632679 0 4.71238898038" xyz="-3.67394039744e-18 -0.02 0.01028"/>
    <axis xyz="0 0 1"/>
    <parent link="wheel_0"/>
    <child link="wheel_0/bar_10"/>
  </joint>
  <gazebo reference="wheel_0/bar_10">
    <mu1>0.5</mu1>
    <mu2>0.5</mu2>
    <material>Gazebo/Black</material>
    <gravity>true</gravity>
    <minDepth>0.0005 </minDepth>
  </gazebo>
  <!-- for bar link -->
  <link name="wheel_0/bar_5">
    <inertial>
      <origin rpy="0 0 0" xyz="0 0 0"/>
      <mass value="0.005"/>
      <!--                <xacro:cylinder_inertia r="0.001" l="0.003" mass="${wheel_bar_mass}"/>-->
      <inertia ixx="0.000000026" ixy="0.0" ixz="0.0" iyy="0.000000026" iyz="0.0" izz="0.000000018"/>
    </inertial>
    <visual>
      <origin rpy="0 0 0" xyz="0 0 0"/>
      <geometry>
        <mesh filename="/home/ou/workspace/ros_ws/src/tricycle/meshes/bar.stl" scale="1.0 1.0 1.0"/>
      </geometry>
    </visual>
    <collision>
      <origin rpy="0 0 0" xyz="0 0 0"/>
      <geometry>
        <mesh filename="/home/ou/workspace/ros_ws/src/tricycle/meshes/bar.stl" scale="1.0 1.0 1.0"/>
      </geometry>
    </collision>
  </link>
  <joint name="wheel_0/bar_joint_5" type="continuous">
    <origin rpy="1.57079632679 0 5.23598775598" xyz="0.01 -0.0173205080757 0.02098"/>
    <axis xyz="0 0 1"/>
    <parent link="wheel_0"/>
    <child link="wheel_0/bar_5"/>
  </joint>
  <gazebo reference="wheel_0/bar_5">
    <mu1>0.5</mu1>
    <mu2>0.5</mu2>
    <material>Gazebo/Black</material>
    <gravity>true</gravity>
    <minDepth>0.0005 </minDepth>
  </gazebo>
  <!-- for bar link -->
  <link name="wheel_0/bar_11">
    <inertial>
      <origin rpy="0 0 0" xyz="0 0 0"/>
      <mass value="0.005"/>
      <!--                <xacro:cylinder_inertia r="0.001" l="0.003" mass="${wheel_bar_mass}"/>-->
      <inertia ixx="0.000000026" ixy="0.0" ixz="0.0" iyy="0.000000026" iyz="0.0" izz="0.000000018"/>
    </inertial>
    <visual>
      <origin rpy="0 0 0" xyz="0 0 0"/>
      <geometry>
        <mesh filename="/home/ou/workspace/ros_ws/src/tricycle/meshes/bar.stl" scale="1.0 1.0 1.0"/>
      </geometry>
    </visual>
    <collision>
      <origin rpy="0 0 0" xyz="0 0 0"/>
      <geometry>
        <mesh filename="/home/ou/workspace/ros_ws/src/tricycle/meshes/bar.stl" scale="1.0 1.0 1.0"/>
      </geometry>
    </collision>
  </link>
  <joint name="wheel_0/bar_joint_11" type="continuous">
    <origin rpy="1.57079632679 0 5.75958653158" xyz="0.0173205080757 -0.01 0.01028"/>
    <axis xyz="0 0 1"/>
    <parent link="wheel_0"/>
    <child link="wheel_0/bar_11"/>
  </joint>
  <gazebo reference="wheel_0/bar_11">
    <mu1>0.5</mu1>
    <mu2>0.5</mu2>
    <material>Gazebo/Black</material>
    <gravity>true</gravity>
    <minDepth>0.0005 </minDepth>
  </gazebo>
  <gazebo laserRetro="0" maxContacts="100" reference="wheel_0" selfCollide="false"/>
  <transmission name="wheel_trans_0">
    <type>transmission_interface/SimpleTransmission</type>
    <joint name="base_wheel_0_joint">
      <hardwareInterface>hardware_interface/EffortJointInterface</hardwareInterface>
    </joint>
    <actuator name="wheel_act_0">
      <hardwareInterface>hardware_interface/EffortJointInterface</hardwareInterface>
      <mechanicalReduction>1</mechanicalReduction>
    </actuator>
  </transmission>
  <!-- for base_wheel joint -->
  <joint name="base_wheel_1_joint" type="continuous">
    <origin rpy="1.57079632679 0 3.66519142919" xyz="-0.0353553390593 0.0612372435696 -0.01"/>
    <axis xyz="0 0 1"/>
    <parent link="base_link"/>
    <child link="wheel_1"/>
    <dynamics damping="0.01" friction="0.1"/>
  </joint>
  <link name="wheel_1">
    <inertial>
      <origin rpy="0 0 0" xyz="0 0 0"/>
      <mass value="0.1"/>
      <!-- [kg] -->
      <inertia ixx="0.0000005" ixy="0.0" ixz="0.0" iyy="0.0000005" iyz="0.0" izz="0.0000007"/>
      <!-- [kg m^2] [kg m^2] [kg m^2] [kg m^2] [kg m^2] [kg m^2] -->
    </inertial>
    <visual>
      <origin rpy="0 0 0" xyz="0 0 0"/>
      <origin rpy="1.57079632679 0 3.66519142919" xyz="-0.0353553390593 0.0612372435696 -0.01"/>
      <geometry>
        <mesh filename="/home/ou/workspace/ros_ws/src/tricycle/meshes/wheel_frame.stl" scale="1 1 1"/>
      </geometry>
    </visual>
    <collision>
      <origin rpy="0 0 0" xyz="0 0 0"/>
      <geometry>
        <mesh filename="/home/ou/workspace/ros_ws/src/tricycle/meshes/wheel_frame.stl" scale="1 1 1"/>
      </geometry>
    </collision>
  </link>
  <!-- for bar link -->
  <link name="wheel_1/bar_0">
    <inertial>
      <origin rpy="0 0 0" xyz="0 0 0"/>
      <mass value="0.005"/>
      <!--                <xacro:cylinder_inertia r="0.001" l="0.003" mass="${wheel_bar_mass}"/>-->
      <inertia ixx="0.000000026" ixy="0.0" ixz="0.0" iyy="0.000000026" iyz="0.0" izz="0.000000018"/>
    </inertial>
    <visual>
      <origin rpy="0 0 0" xyz="0 0 0"/>
      <geometry>
        <mesh filename="/home/ou/workspace/ros_ws/src/tricycle/meshes/bar.stl" scale="1.0 1.0 1.0"/>
      </geometry>
    </visual>
    <collision>
      <origin rpy="0 0 0" xyz="0 0 0"/>
      <geometry>
        <mesh filename="/home/ou/workspace/ros_ws/src/tricycle/meshes/bar.stl" scale="1.0 1.0 1.0"/>
      </geometry>
    </collision>
  </link>
  <joint name="wheel_1/bar_joint_0" type="continuous">
    <origin rpy="1.57079632679 0 0.0" xyz="0.02 0.0 0.02098"/>
    <axis xyz="0 0 1"/>
    <parent link="wheel_1"/>
    <child link="wheel_1/bar_0"/>
  </joint>
  <gazebo reference="wheel_1/bar_0">
    <mu1>0.5</mu1>
    <mu2>0.5</mu2>
    <material>Gazebo/Black</material>
    <gravity>true</gravity>
    <minDepth>0.0005 </minDepth>
  </gazebo>
  <!-- for bar link -->
  <link name="wheel_1/bar_6">
    <inertial>
      <origin rpy="0 0 0" xyz="0 0 0"/>
      <mass value="0.005"/>
      <!--                <xacro:cylinder_inertia r="0.001" l="0.003" mass="${wheel_bar_mass}"/>-->
      <inertia ixx="0.000000026" ixy="0.0" ixz="0.0" iyy="0.000000026" iyz="0.0" izz="0.000000018"/>
    </inertial>
    <visual>
      <origin rpy="0 0 0" xyz="0 0 0"/>
      <geometry>
        <mesh filename="/home/ou/workspace/ros_ws/src/tricycle/meshes/bar.stl" scale="1.0 1.0 1.0"/>
      </geometry>
    </visual>
    <collision>
      <origin rpy="0 0 0" xyz="0 0 0"/>
      <geometry>
        <mesh filename="/home/ou/workspace/ros_ws/src/tricycle/meshes/bar.stl" scale="1.0 1.0 1.0"/>
      </geometry>
    </collision>
  </link>
  <joint name="wheel_1/bar_joint_6" type="continuous">
    <origin rpy="1.57079632679 0 0.523598775598" xyz="0.0173205080757 0.01 0.01028"/>
    <axis xyz="0 0 1"/>
    <parent link="wheel_1"/>
    <child link="wheel_1/bar_6"/>
  </joint>
  <gazebo reference="wheel_1/bar_6">
    <mu1>0.5</mu1>
    <mu2>0.5</mu2>
    <material>Gazebo/Black</material>
    <gravity>true</gravity>
    <minDepth>0.0005 </minDepth>
  </gazebo>
  <!-- for bar link -->
  <link name="wheel_1/bar_1">
    <inertial>
      <origin rpy="0 0 0" xyz="0 0 0"/>
      <mass value="0.005"/>
      <!--                <xacro:cylinder_inertia r="0.001" l="0.003" mass="${wheel_bar_mass}"/>-->
      <inertia ixx="0.000000026" ixy="0.0" ixz="0.0" iyy="0.000000026" iyz="0.0" izz="0.000000018"/>
    </inertial>
    <visual>
      <origin rpy="0 0 0" xyz="0 0 0"/>
      <geometry>
        <mesh filename="/home/ou/workspace/ros_ws/src/tricycle/meshes/bar.stl" scale="1.0 1.0 1.0"/>
      </geometry>
    </visual>
    <collision>
      <origin rpy="0 0 0" xyz="0 0 0"/>
      <geometry>
        <mesh filename="/home/ou/workspace/ros_ws/src/tricycle/meshes/bar.stl" scale="1.0 1.0 1.0"/>
      </geometry>
    </collision>
  </link>
  <joint name="wheel_1/bar_joint_1" type="continuous">
    <origin rpy="1.57079632679 0 1.0471975512" xyz="0.01 0.0173205080757 0.02098"/>
    <axis xyz="0 0 1"/>
    <parent link="wheel_1"/>
    <child link="wheel_1/bar_1"/>
  </joint>
  <gazebo reference="wheel_1/bar_1">
    <mu1>0.5</mu1>
    <mu2>0.5</mu2>
    <material>Gazebo/Black</material>
    <gravity>true</gravity>
    <minDepth>0.0005 </minDepth>
  </gazebo>
  <!-- for bar link -->
  <link name="wheel_1/bar_7">
    <inertial>
      <origin rpy="0 0 0" xyz="0 0 0"/>
      <mass value="0.005"/>
      <!--                <xacro:cylinder_inertia r="0.001" l="0.003" mass="${wheel_bar_mass}"/>-->
      <inertia ixx="0.000000026" ixy="0.0" ixz="0.0" iyy="0.000000026" iyz="0.0" izz="0.000000018"/>
    </inertial>
    <visual>
      <origin rpy="0 0 0" xyz="0 0 0"/>
      <geometry>
        <mesh filename="/home/ou/workspace/ros_ws/src/tricycle/meshes/bar.stl" scale="1.0 1.0 1.0"/>
      </geometry>
    </visual>
    <collision>
      <origin rpy="0 0 0" xyz="0 0 0"/>
      <geometry>
        <mesh filename="/home/ou/workspace/ros_ws/src/tricycle/meshes/bar.stl" scale="1.0 1.0 1.0"/>
      </geometry>
    </collision>
  </link>
  <joint name="wheel_1/bar_joint_7" type="continuous">
    <origin rpy="1.57079632679 0 1.57079632679" xyz="1.22464679915e-18 0.02 0.01028"/>
    <axis xyz="0 0 1"/>
    <parent link="wheel_1"/>
    <child link="wheel_1/bar_7"/>
  </joint>
  <gazebo reference="wheel_1/bar_7">
    <mu1>0.5</mu1>
    <mu2>0.5</mu2>
    <material>Gazebo/Black</material>
    <gravity>true</gravity>
    <minDepth>0.0005 </minDepth>
  </gazebo>
  <!-- for bar link -->
  <link name="wheel_1/bar_2">
    <inertial>
      <origin rpy="0 0 0" xyz="0 0 0"/>
      <mass value="0.005"/>
      <!--                <xacro:cylinder_inertia r="0.001" l="0.003" mass="${wheel_bar_mass}"/>-->
      <inertia ixx="0.000000026" ixy="0.0" ixz="0.0" iyy="0.000000026" iyz="0.0" izz="0.000000018"/>
    </inertial>
    <visual>
      <origin rpy="0 0 0" xyz="0 0 0"/>
      <geometry>
        <mesh filename="/home/ou/workspace/ros_ws/src/tricycle/meshes/bar.stl" scale="1.0 1.0 1.0"/>
      </geometry>
    </visual>
    <collision>
      <origin rpy="0 0 0" xyz="0 0 0"/>
      <geometry>
        <mesh filename="/home/ou/workspace/ros_ws/src/tricycle/meshes/bar.stl" scale="1.0 1.0 1.0"/>
      </geometry>
    </collision>
  </link>
  <joint name="wheel_1/bar_joint_2" type="continuous">
    <origin rpy="1.57079632679 0 2.09439510239" xyz="-0.01 0.0173205080757 0.02098"/>
    <axis xyz="0 0 1"/>
    <parent link="wheel_1"/>
    <child link="wheel_1/bar_2"/>
  </joint>
  <gazebo reference="wheel_1/bar_2">
    <mu1>0.5</mu1>
    <mu2>0.5</mu2>
    <material>Gazebo/Black</material>
    <gravity>true</gravity>
    <minDepth>0.0005 </minDepth>
  </gazebo>
  <!-- for bar link -->
  <link name="wheel_1/bar_8">
    <inertial>
      <origin rpy="0 0 0" xyz="0 0 0"/>
      <mass value="0.005"/>
      <!--                <xacro:cylinder_inertia r="0.001" l="0.003" mass="${wheel_bar_mass}"/>-->
      <inertia ixx="0.000000026" ixy="0.0" ixz="0.0" iyy="0.000000026" iyz="0.0" izz="0.000000018"/>
    </inertial>
    <visual>
      <origin rpy="0 0 0" xyz="0 0 0"/>
      <geometry>
        <mesh filename="/home/ou/workspace/ros_ws/src/tricycle/meshes/bar.stl" scale="1.0 1.0 1.0"/>
      </geometry>
    </visual>
    <collision>
      <origin rpy="0 0 0" xyz="0 0 0"/>
      <geometry>
        <mesh filename="/home/ou/workspace/ros_ws/src/tricycle/meshes/bar.stl" scale="1.0 1.0 1.0"/>
      </geometry>
    </collision>
  </link>
  <joint name="wheel_1/bar_joint_8" type="continuous">
    <origin rpy="1.57079632679 0 2.61799387799" xyz="-0.0173205080757 0.01 0.01028"/>
    <axis xyz="0 0 1"/>
    <parent link="wheel_1"/>
    <child link="wheel_1/bar_8"/>
  </joint>
  <gazebo reference="wheel_1/bar_8">
    <mu1>0.5</mu1>
    <mu2>0.5</mu2>
    <material>Gazebo/Black</material>
    <gravity>true</gravity>
    <minDepth>0.0005 </minDepth>
  </gazebo>
  <!-- for bar link -->
  <link name="wheel_1/bar_3">
    <inertial>
      <origin rpy="0 0 0" xyz="0 0 0"/>
      <mass value="0.005"/>
      <!--                <xacro:cylinder_inertia r="0.001" l="0.003" mass="${wheel_bar_mass}"/>-->
      <inertia ixx="0.000000026" ixy="0.0" ixz="0.0" iyy="0.000000026" iyz="0.0" izz="0.000000018"/>
    </inertial>
    <visual>
      <origin rpy="0 0 0" xyz="0 0 0"/>
      <geometry>
        <mesh filename="/home/ou/workspace/ros_ws/src/tricycle/meshes/bar.stl" scale="1.0 1.0 1.0"/>
      </geometry>
    </visual>
    <collision>
      <origin rpy="0 0 0" xyz="0 0 0"/>
      <geometry>
        <mesh filename="/home/ou/workspace/ros_ws/src/tricycle/meshes/bar.stl" scale="1.0 1.0 1.0"/>
      </geometry>
    </collision>
  </link>
  <joint name="wheel_1/bar_joint_3" type="continuous">
    <origin rpy="1.57079632679 0 3.14159265359" xyz="-0.02 2.44929359829e-18 0.02098"/>
    <axis xyz="0 0 1"/>
    <parent link="wheel_1"/>
    <child link="wheel_1/bar_3"/>
  </joint>
  <gazebo reference="wheel_1/bar_3">
    <mu1>0.5</mu1>
    <mu2>0.5</mu2>
    <material>Gazebo/Black</material>
    <gravity>true</gravity>
    <minDepth>0.0005 </minDepth>
  </gazebo>
  <!-- for bar link -->
  <link name="wheel_1/bar_9">
    <inertial>
      <origin rpy="0 0 0" xyz="0 0 0"/>
      <mass value="0.005"/>
      <!--                <xacro:cylinder_inertia r="0.001" l="0.003" mass="${wheel_bar_mass}"/>-->
      <inertia ixx="0.000000026" ixy="0.0" ixz="0.0" iyy="0.000000026" iyz="0.0" izz="0.000000018"/>
    </inertial>
    <visual>
      <origin rpy="0 0 0" xyz="0 0 0"/>
      <geometry>
        <mesh filename="/home/ou/workspace/ros_ws/src/tricycle/meshes/bar.stl" scale="1.0 1.0 1.0"/>
      </geometry>
    </visual>
    <collision>
      <origin rpy="0 0 0" xyz="0 0 0"/>
      <geometry>
        <mesh filename="/home/ou/workspace/ros_ws/src/tricycle/meshes/bar.stl" scale="1.0 1.0 1.0"/>
      </geometry>
    </collision>
  </link>
  <joint name="wheel_1/bar_joint_9" type="continuous">
    <origin rpy="1.57079632679 0 3.66519142919" xyz="-0.0173205080757 -0.01 0.01028"/>
    <axis xyz="0 0 1"/>
    <parent link="wheel_1"/>
    <child link="wheel_1/bar_9"/>
  </joint>
  <gazebo reference="wheel_1/bar_9">
    <mu1>0.5</mu1>
    <mu2>0.5</mu2>
    <material>Gazebo/Black</material>
    <gravity>true</gravity>
    <minDepth>0.0005 </minDepth>
  </gazebo>
  <!-- for bar link -->
  <link name="wheel_1/bar_4">
    <inertial>
      <origin rpy="0 0 0" xyz="0 0 0"/>
      <mass value="0.005"/>
      <!--                <xacro:cylinder_inertia r="0.001" l="0.003" mass="${wheel_bar_mass}"/>-->
      <inertia ixx="0.000000026" ixy="0.0" ixz="0.0" iyy="0.000000026" iyz="0.0" izz="0.000000018"/>
    </inertial>
    <visual>
      <origin rpy="0 0 0" xyz="0 0 0"/>
      <geometry>
        <mesh filename="/home/ou/workspace/ros_ws/src/tricycle/meshes/bar.stl" scale="1.0 1.0 1.0"/>
      </geometry>
    </visual>
    <collision>
      <origin rpy="0 0 0" xyz="0 0 0"/>
      <geometry>
        <mesh filename="/home/ou/workspace/ros_ws/src/tricycle/meshes/bar.stl" scale="1.0 1.0 1.0"/>
      </geometry>
    </collision>
  </link>
  <joint name="wheel_1/bar_joint_4" type="continuous">
    <origin rpy="1.57079632679 0 4.18879020479" xyz="-0.01 -0.0173205080757 0.02098"/>
    <axis xyz="0 0 1"/>
    <parent link="wheel_1"/>
    <child link="wheel_1/bar_4"/>
  </joint>
  <gazebo reference="wheel_1/bar_4">
    <mu1>0.5</mu1>
    <mu2>0.5</mu2>
    <material>Gazebo/Black</material>
    <gravity>true</gravity>
    <minDepth>0.0005 </minDepth>
  </gazebo>
  <!-- for bar link -->
  <link name="wheel_1/bar_10">
    <inertial>
      <origin rpy="0 0 0" xyz="0 0 0"/>
      <mass value="0.005"/>
      <!--                <xacro:cylinder_inertia r="0.001" l="0.003" mass="${wheel_bar_mass}"/>-->
      <inertia ixx="0.000000026" ixy="0.0" ixz="0.0" iyy="0.000000026" iyz="0.0" izz="0.000000018"/>
    </inertial>
    <visual>
      <origin rpy="0 0 0" xyz="0 0 0"/>
      <geometry>
        <mesh filename="/home/ou/workspace/ros_ws/src/tricycle/meshes/bar.stl" scale="1.0 1.0 1.0"/>
      </geometry>
    </visual>
    <collision>
      <origin rpy="0 0 0" xyz="0 0 0"/>
      <geometry>
        <mesh filename="/home/ou/workspace/ros_ws/src/tricycle/meshes/bar.stl" scale="1.0 1.0 1.0"/>
      </geometry>
    </collision>
  </link>
  <joint name="wheel_1/bar_joint_10" type="continuous">
    <origin rpy="1.57079632679 0 4.71238898038" xyz="-3.67394039744e-18 -0.02 0.01028"/>
    <axis xyz="0 0 1"/>
    <parent link="wheel_1"/>
    <child link="wheel_1/bar_10"/>
  </joint>
  <gazebo reference="wheel_1/bar_10">
    <mu1>0.5</mu1>
    <mu2>0.5</mu2>
    <material>Gazebo/Black</material>
    <gravity>true</gravity>
    <minDepth>0.0005 </minDepth>
  </gazebo>
  <!-- for bar link -->
  <link name="wheel_1/bar_5">
    <inertial>
      <origin rpy="0 0 0" xyz="0 0 0"/>
      <mass value="0.005"/>
      <!--                <xacro:cylinder_inertia r="0.001" l="0.003" mass="${wheel_bar_mass}"/>-->
      <inertia ixx="0.000000026" ixy="0.0" ixz="0.0" iyy="0.000000026" iyz="0.0" izz="0.000000018"/>
    </inertial>
    <visual>
      <origin rpy="0 0 0" xyz="0 0 0"/>
      <geometry>
        <mesh filename="/home/ou/workspace/ros_ws/src/tricycle/meshes/bar.stl" scale="1.0 1.0 1.0"/>
      </geometry>
    </visual>
    <collision>
      <origin rpy="0 0 0" xyz="0 0 0"/>
      <geometry>
        <mesh filename="/home/ou/workspace/ros_ws/src/tricycle/meshes/bar.stl" scale="1.0 1.0 1.0"/>
      </geometry>
    </collision>
  </link>
  <joint name="wheel_1/bar_joint_5" type="continuous">
    <origin rpy="1.57079632679 0 5.23598775598" xyz="0.01 -0.0173205080757 0.02098"/>
    <axis xyz="0 0 1"/>
    <parent link="wheel_1"/>
    <child link="wheel_1/bar_5"/>
  </joint>
  <gazebo reference="wheel_1/bar_5">
    <mu1>0.5</mu1>
    <mu2>0.5</mu2>
    <material>Gazebo/Black</material>
    <gravity>true</gravity>
    <minDepth>0.0005 </minDepth>
  </gazebo>
  <!-- for bar link -->
  <link name="wheel_1/bar_11">
    <inertial>
      <origin rpy="0 0 0" xyz="0 0 0"/>
      <mass value="0.005"/>
      <!--                <xacro:cylinder_inertia r="0.001" l="0.003" mass="${wheel_bar_mass}"/>-->
      <inertia ixx="0.000000026" ixy="0.0" ixz="0.0" iyy="0.000000026" iyz="0.0" izz="0.000000018"/>
    </inertial>
    <visual>
      <origin rpy="0 0 0" xyz="0 0 0"/>
      <geometry>
        <mesh filename="/home/ou/workspace/ros_ws/src/tricycle/meshes/bar.stl" scale="1.0 1.0 1.0"/>
      </geometry>
    </visual>
    <collision>
      <origin rpy="0 0 0" xyz="0 0 0"/>
      <geometry>
        <mesh filename="/home/ou/workspace/ros_ws/src/tricycle/meshes/bar.stl" scale="1.0 1.0 1.0"/>
      </geometry>
    </collision>
  </link>
  <joint name="wheel_1/bar_joint_11" type="continuous">
    <origin rpy="1.57079632679 0 5.75958653158" xyz="0.0173205080757 -0.01 0.01028"/>
    <axis xyz="0 0 1"/>
    <parent link="wheel_1"/>
    <child link="wheel_1/bar_11"/>
  </joint>
  <gazebo reference="wheel_1/bar_11">
    <mu1>0.5</mu1>
    <mu2>0.5</mu2>
    <material>Gazebo/Black</material>
    <gravity>true</gravity>
    <minDepth>0.0005 </minDepth>
  </gazebo>
  <gazebo laserRetro="0" maxContacts="100" reference="wheel_1" selfCollide="false"/>
  <transmission name="wheel_trans_1">
    <type>transmission_interface/SimpleTransmission</type>
    <joint name="base_wheel_1_joint">
      <hardwareInterface>hardware_interface/EffortJointInterface</hardwareInterface>
    </joint>
    <actuator name="wheel_act_1">
      <hardwareInterface>hardware_interface/EffortJointInterface</hardwareInterface>
      <mechanicalReduction>1</mechanicalReduction>
    </actuator>
  </transmission>
  <!-- for base_wheel joint -->
  <joint name="base_wheel_2_joint" type="continuous">
    <origin rpy="1.57079632679 0 5.75958653158" xyz="-0.0353553390593 -0.0612372435696 -0.01"/>
    <axis xyz="0 0 1"/>
    <parent link="base_link"/>
    <child link="wheel_2"/>
    <dynamics damping="0.01" friction="0.1"/>
  </joint>
  <link name="wheel_2">
    <inertial>
      <origin rpy="0 0 0" xyz="0 0 0"/>
      <mass value="0.1"/>
      <!-- [kg] -->
      <inertia ixx="0.0000005" ixy="0.0" ixz="0.0" iyy="0.0000005" iyz="0.0" izz="0.0000007"/>
      <!-- [kg m^2] [kg m^2] [kg m^2] [kg m^2] [kg m^2] [kg m^2] -->
    </inertial>
    <visual>
      <origin rpy="0 0 0" xyz="0 0 0"/>
      <origin rpy="1.57079632679 0 5.75958653158" xyz="-0.0353553390593 -0.0612372435696 -0.01"/>
      <geometry>
        <mesh filename="/home/ou/workspace/ros_ws/src/tricycle/meshes/wheel_frame.stl" scale="1 1 1"/>
      </geometry>
    </visual>
    <collision>
      <origin rpy="0 0 0" xyz="0 0 0"/>
      <geometry>
        <mesh filename="/home/ou/workspace/ros_ws/src/tricycle/meshes/wheel_frame.stl" scale="1 1 1"/>
      </geometry>
    </collision>
  </link>
  <!-- for bar link -->
  <link name="wheel_2/bar_0">
    <inertial>
      <origin rpy="0 0 0" xyz="0 0 0"/>
      <mass value="0.005"/>
      <!--                <xacro:cylinder_inertia r="0.001" l="0.003" mass="${wheel_bar_mass}"/>-->
      <inertia ixx="0.000000026" ixy="0.0" ixz="0.0" iyy="0.000000026" iyz="0.0" izz="0.000000018"/>
    </inertial>
    <visual>
      <origin rpy="0 0 0" xyz="0 0 0"/>
      <geometry>
        <mesh filename="/home/ou/workspace/ros_ws/src/tricycle/meshes/bar.stl" scale="1.0 1.0 1.0"/>
      </geometry>
    </visual>
    <collision>
      <origin rpy="0 0 0" xyz="0 0 0"/>
      <geometry>
        <mesh filename="/home/ou/workspace/ros_ws/src/tricycle/meshes/bar.stl" scale="1.0 1.0 1.0"/>
      </geometry>
    </collision>
  </link>
  <joint name="wheel_2/bar_joint_0" type="continuous">
    <origin rpy="1.57079632679 0 0.0" xyz="0.02 0.0 0.02098"/>
    <axis xyz="0 0 1"/>
    <parent link="wheel_2"/>
    <child link="wheel_2/bar_0"/>
  </joint>
  <gazebo reference="wheel_2/bar_0">
    <mu1>0.5</mu1>
    <mu2>0.5</mu2>
    <material>Gazebo/Black</material>
    <gravity>true</gravity>
    <minDepth>0.0005 </minDepth>
  </gazebo>
  <!-- for bar link -->
  <link name="wheel_2/bar_6">
    <inertial>
      <origin rpy="0 0 0" xyz="0 0 0"/>
      <mass value="0.005"/>
      <!--                <xacro:cylinder_inertia r="0.001" l="0.003" mass="${wheel_bar_mass}"/>-->
      <inertia ixx="0.000000026" ixy="0.0" ixz="0.0" iyy="0.000000026" iyz="0.0" izz="0.000000018"/>
    </inertial>
    <visual>
      <origin rpy="0 0 0" xyz="0 0 0"/>
      <geometry>
        <mesh filename="/home/ou/workspace/ros_ws/src/tricycle/meshes/bar.stl" scale="1.0 1.0 1.0"/>
      </geometry>
    </visual>
    <collision>
      <origin rpy="0 0 0" xyz="0 0 0"/>
      <geometry>
        <mesh filename="/home/ou/workspace/ros_ws/src/tricycle/meshes/bar.stl" scale="1.0 1.0 1.0"/>
      </geometry>
    </collision>
  </link>
  <joint name="wheel_2/bar_joint_6" type="continuous">
    <origin rpy="1.57079632679 0 0.523598775598" xyz="0.0173205080757 0.01 0.01028"/>
    <axis xyz="0 0 1"/>
    <parent link="wheel_2"/>
    <child link="wheel_2/bar_6"/>
  </joint>
  <gazebo reference="wheel_2/bar_6">
    <mu1>0.5</mu1>
    <mu2>0.5</mu2>
    <material>Gazebo/Black</material>
    <gravity>true</gravity>
    <minDepth>0.0005 </minDepth>
  </gazebo>
  <!-- for bar link -->
  <link name="wheel_2/bar_1">
    <inertial>
      <origin rpy="0 0 0" xyz="0 0 0"/>
      <mass value="0.005"/>
      <!--                <xacro:cylinder_inertia r="0.001" l="0.003" mass="${wheel_bar_mass}"/>-->
      <inertia ixx="0.000000026" ixy="0.0" ixz="0.0" iyy="0.000000026" iyz="0.0" izz="0.000000018"/>
    </inertial>
    <visual>
      <origin rpy="0 0 0" xyz="0 0 0"/>
      <geometry>
        <mesh filename="/home/ou/workspace/ros_ws/src/tricycle/meshes/bar.stl" scale="1.0 1.0 1.0"/>
      </geometry>
    </visual>
    <collision>
      <origin rpy="0 0 0" xyz="0 0 0"/>
      <geometry>
        <mesh filename="/home/ou/workspace/ros_ws/src/tricycle/meshes/bar.stl" scale="1.0 1.0 1.0"/>
      </geometry>
    </collision>
  </link>
  <joint name="wheel_2/bar_joint_1" type="continuous">
    <origin rpy="1.57079632679 0 1.0471975512" xyz="0.01 0.0173205080757 0.02098"/>
    <axis xyz="0 0 1"/>
    <parent link="wheel_2"/>
    <child link="wheel_2/bar_1"/>
  </joint>
  <gazebo reference="wheel_2/bar_1">
    <mu1>0.5</mu1>
    <mu2>0.5</mu2>
    <material>Gazebo/Black</material>
    <gravity>true</gravity>
    <minDepth>0.0005 </minDepth>
  </gazebo>
  <!-- for bar link -->
  <link name="wheel_2/bar_7">
    <inertial>
      <origin rpy="0 0 0" xyz="0 0 0"/>
      <mass value="0.005"/>
      <!--                <xacro:cylinder_inertia r="0.001" l="0.003" mass="${wheel_bar_mass}"/>-->
      <inertia ixx="0.000000026" ixy="0.0" ixz="0.0" iyy="0.000000026" iyz="0.0" izz="0.000000018"/>
    </inertial>
    <visual>
      <origin rpy="0 0 0" xyz="0 0 0"/>
      <geometry>
        <mesh filename="/home/ou/workspace/ros_ws/src/tricycle/meshes/bar.stl" scale="1.0 1.0 1.0"/>
      </geometry>
    </visual>
    <collision>
      <origin rpy="0 0 0" xyz="0 0 0"/>
      <geometry>
        <mesh filename="/home/ou/workspace/ros_ws/src/tricycle/meshes/bar.stl" scale="1.0 1.0 1.0"/>
      </geometry>
    </collision>
  </link>
  <joint name="wheel_2/bar_joint_7" type="continuous">
    <origin rpy="1.57079632679 0 1.57079632679" xyz="1.22464679915e-18 0.02 0.01028"/>
    <axis xyz="0 0 1"/>
    <parent link="wheel_2"/>
    <child link="wheel_2/bar_7"/>
  </joint>
  <gazebo reference="wheel_2/bar_7">
    <mu1>0.5</mu1>
    <mu2>0.5</mu2>
    <material>Gazebo/Black</material>
    <gravity>true</gravity>
    <minDepth>0.0005 </minDepth>
  </gazebo>
  <!-- for bar link -->
  <link name="wheel_2/bar_2">
    <inertial>
      <origin rpy="0 0 0" xyz="0 0 0"/>
      <mass value="0.005"/>
      <!--                <xacro:cylinder_inertia r="0.001" l="0.003" mass="${wheel_bar_mass}"/>-->
      <inertia ixx="0.000000026" ixy="0.0" ixz="0.0" iyy="0.000000026" iyz="0.0" izz="0.000000018"/>
    </inertial>
    <visual>
      <origin rpy="0 0 0" xyz="0 0 0"/>
      <geometry>
        <mesh filename="/home/ou/workspace/ros_ws/src/tricycle/meshes/bar.stl" scale="1.0 1.0 1.0"/>
      </geometry>
    </visual>
    <collision>
      <origin rpy="0 0 0" xyz="0 0 0"/>
      <geometry>
        <mesh filename="/home/ou/workspace/ros_ws/src/tricycle/meshes/bar.stl" scale="1.0 1.0 1.0"/>
      </geometry>
    </collision>
  </link>
  <joint name="wheel_2/bar_joint_2" type="continuous">
    <origin rpy="1.57079632679 0 2.09439510239" xyz="-0.01 0.0173205080757 0.02098"/>
    <axis xyz="0 0 1"/>
    <parent link="wheel_2"/>
    <child link="wheel_2/bar_2"/>
  </joint>
  <gazebo reference="wheel_2/bar_2">
    <mu1>0.5</mu1>
    <mu2>0.5</mu2>
    <material>Gazebo/Black</material>
    <gravity>true</gravity>
    <minDepth>0.0005 </minDepth>
  </gazebo>
  <!-- for bar link -->
  <link name="wheel_2/bar_8">
    <inertial>
      <origin rpy="0 0 0" xyz="0 0 0"/>
      <mass value="0.005"/>
      <!--                <xacro:cylinder_inertia r="0.001" l="0.003" mass="${wheel_bar_mass}"/>-->
      <inertia ixx="0.000000026" ixy="0.0" ixz="0.0" iyy="0.000000026" iyz="0.0" izz="0.000000018"/>
    </inertial>
    <visual>
      <origin rpy="0 0 0" xyz="0 0 0"/>
      <geometry>
        <mesh filename="/home/ou/workspace/ros_ws/src/tricycle/meshes/bar.stl" scale="1.0 1.0 1.0"/>
      </geometry>
    </visual>
    <collision>
      <origin rpy="0 0 0" xyz="0 0 0"/>
      <geometry>
        <mesh filename="/home/ou/workspace/ros_ws/src/tricycle/meshes/bar.stl" scale="1.0 1.0 1.0"/>
      </geometry>
    </collision>
  </link>
  <joint name="wheel_2/bar_joint_8" type="continuous">
    <origin rpy="1.57079632679 0 2.61799387799" xyz="-0.0173205080757 0.01 0.01028"/>
    <axis xyz="0 0 1"/>
    <parent link="wheel_2"/>
    <child link="wheel_2/bar_8"/>
  </joint>
  <gazebo reference="wheel_2/bar_8">
    <mu1>0.5</mu1>
    <mu2>0.5</mu2>
    <material>Gazebo/Black</material>
    <gravity>true</gravity>
    <minDepth>0.0005 </minDepth>
  </gazebo>
  <!-- for bar link -->
  <link name="wheel_2/bar_3">
    <inertial>
      <origin rpy="0 0 0" xyz="0 0 0"/>
      <mass value="0.005"/>
      <!--                <xacro:cylinder_inertia r="0.001" l="0.003" mass="${wheel_bar_mass}"/>-->
      <inertia ixx="0.000000026" ixy="0.0" ixz="0.0" iyy="0.000000026" iyz="0.0" izz="0.000000018"/>
    </inertial>
    <visual>
      <origin rpy="0 0 0" xyz="0 0 0"/>
      <geometry>
        <mesh filename="/home/ou/workspace/ros_ws/src/tricycle/meshes/bar.stl" scale="1.0 1.0 1.0"/>
      </geometry>
    </visual>
    <collision>
      <origin rpy="0 0 0" xyz="0 0 0"/>
      <geometry>
        <mesh filename="/home/ou/workspace/ros_ws/src/tricycle/meshes/bar.stl" scale="1.0 1.0 1.0"/>
      </geometry>
    </collision>
  </link>
  <joint name="wheel_2/bar_joint_3" type="continuous">
    <origin rpy="1.57079632679 0 3.14159265359" xyz="-0.02 2.44929359829e-18 0.02098"/>
    <axis xyz="0 0 1"/>
    <parent link="wheel_2"/>
    <child link="wheel_2/bar_3"/>
  </joint>
  <gazebo reference="wheel_2/bar_3">
    <mu1>0.5</mu1>
    <mu2>0.5</mu2>
    <material>Gazebo/Black</material>
    <gravity>true</gravity>
    <minDepth>0.0005 </minDepth>
  </gazebo>
  <!-- for bar link -->
  <link name="wheel_2/bar_9">
    <inertial>
      <origin rpy="0 0 0" xyz="0 0 0"/>
      <mass value="0.005"/>
      <!--                <xacro:cylinder_inertia r="0.001" l="0.003" mass="${wheel_bar_mass}"/>-->
      <inertia ixx="0.000000026" ixy="0.0" ixz="0.0" iyy="0.000000026" iyz="0.0" izz="0.000000018"/>
    </inertial>
    <visual>
      <origin rpy="0 0 0" xyz="0 0 0"/>
      <geometry>
        <mesh filename="/home/ou/workspace/ros_ws/src/tricycle/meshes/bar.stl" scale="1.0 1.0 1.0"/>
      </geometry>
    </visual>
    <collision>
      <origin rpy="0 0 0" xyz="0 0 0"/>
      <geometry>
        <mesh filename="/home/ou/workspace/ros_ws/src/tricycle/meshes/bar.stl" scale="1.0 1.0 1.0"/>
      </geometry>
    </collision>
  </link>
  <joint name="wheel_2/bar_joint_9" type="continuous">
    <origin rpy="1.57079632679 0 3.66519142919" xyz="-0.0173205080757 -0.01 0.01028"/>
    <axis xyz="0 0 1"/>
    <parent link="wheel_2"/>
    <child link="wheel_2/bar_9"/>
  </joint>
  <gazebo reference="wheel_2/bar_9">
    <mu1>0.5</mu1>
    <mu2>0.5</mu2>
    <material>Gazebo/Black</material>
    <gravity>true</gravity>
    <minDepth>0.0005 </minDepth>
  </gazebo>
  <!-- for bar link -->
  <link name="wheel_2/bar_4">
    <inertial>
      <origin rpy="0 0 0" xyz="0 0 0"/>
      <mass value="0.005"/>
      <!--                <xacro:cylinder_inertia r="0.001" l="0.003" mass="${wheel_bar_mass}"/>-->
      <inertia ixx="0.000000026" ixy="0.0" ixz="0.0" iyy="0.000000026" iyz="0.0" izz="0.000000018"/>
    </inertial>
    <visual>
      <origin rpy="0 0 0" xyz="0 0 0"/>
      <geometry>
        <mesh filename="/home/ou/workspace/ros_ws/src/tricycle/meshes/bar.stl" scale="1.0 1.0 1.0"/>
      </geometry>
    </visual>
    <collision>
      <origin rpy="0 0 0" xyz="0 0 0"/>
      <geometry>
        <mesh filename="/home/ou/workspace/ros_ws/src/tricycle/meshes/bar.stl" scale="1.0 1.0 1.0"/>
      </geometry>
    </collision>
  </link>
  <joint name="wheel_2/bar_joint_4" type="continuous">
    <origin rpy="1.57079632679 0 4.18879020479" xyz="-0.01 -0.0173205080757 0.02098"/>
    <axis xyz="0 0 1"/>
    <parent link="wheel_2"/>
    <child link="wheel_2/bar_4"/>
  </joint>
  <gazebo reference="wheel_2/bar_4">
    <mu1>0.5</mu1>
    <mu2>0.5</mu2>
    <material>Gazebo/Black</material>
    <gravity>true</gravity>
    <minDepth>0.0005 </minDepth>
  </gazebo>
  <!-- for bar link -->
  <link name="wheel_2/bar_10">
    <inertial>
      <origin rpy="0 0 0" xyz="0 0 0"/>
      <mass value="0.005"/>
      <!--                <xacro:cylinder_inertia r="0.001" l="0.003" mass="${wheel_bar_mass}"/>-->
      <inertia ixx="0.000000026" ixy="0.0" ixz="0.0" iyy="0.000000026" iyz="0.0" izz="0.000000018"/>
    </inertial>
    <visual>
      <origin rpy="0 0 0" xyz="0 0 0"/>
      <geometry>
        <mesh filename="/home/ou/workspace/ros_ws/src/tricycle/meshes/bar.stl" scale="1.0 1.0 1.0"/>
      </geometry>
    </visual>
    <collision>
      <origin rpy="0 0 0" xyz="0 0 0"/>
      <geometry>
        <mesh filename="/home/ou/workspace/ros_ws/src/tricycle/meshes/bar.stl" scale="1.0 1.0 1.0"/>
      </geometry>
    </collision>
  </link>
  <joint name="wheel_2/bar_joint_10" type="continuous">
    <origin rpy="1.57079632679 0 4.71238898038" xyz="-3.67394039744e-18 -0.02 0.01028"/>
    <axis xyz="0 0 1"/>
    <parent link="wheel_2"/>
    <child link="wheel_2/bar_10"/>
  </joint>
  <gazebo reference="wheel_2/bar_10">
    <mu1>0.5</mu1>
    <mu2>0.5</mu2>
    <material>Gazebo/Black</material>
    <gravity>true</gravity>
    <minDepth>0.0005 </minDepth>
  </gazebo>
  <!-- for bar link -->
  <link name="wheel_2/bar_5">
    <inertial>
      <origin rpy="0 0 0" xyz="0 0 0"/>
      <mass value="0.005"/>
      <!--                <xacro:cylinder_inertia r="0.001" l="0.003" mass="${wheel_bar_mass}"/>-->
      <inertia ixx="0.000000026" ixy="0.0" ixz="0.0" iyy="0.000000026" iyz="0.0" izz="0.000000018"/>
    </inertial>
    <visual>
      <origin rpy="0 0 0" xyz="0 0 0"/>
      <geometry>
        <mesh filename="/home/ou/workspace/ros_ws/src/tricycle/meshes/bar.stl" scale="1.0 1.0 1.0"/>
      </geometry>
    </visual>
    <collision>
      <origin rpy="0 0 0" xyz="0 0 0"/>
      <geometry>
        <mesh filename="/home/ou/workspace/ros_ws/src/tricycle/meshes/bar.stl" scale="1.0 1.0 1.0"/>
      </geometry>
    </collision>
  </link>
  <joint name="wheel_2/bar_joint_5" type="continuous">
    <origin rpy="1.57079632679 0 5.23598775598" xyz="0.01 -0.0173205080757 0.02098"/>
    <axis xyz="0 0 1"/>
    <parent link="wheel_2"/>
    <child link="wheel_2/bar_5"/>
  </joint>
  <gazebo reference="wheel_2/bar_5">
    <mu1>0.5</mu1>
    <mu2>0.5</mu2>
    <material>Gazebo/Black</material>
    <gravity>true</gravity>
    <minDepth>0.0005 </minDepth>
  </gazebo>
  <!-- for bar link -->
  <link name="wheel_2/bar_11">
    <inertial>
      <origin rpy="0 0 0" xyz="0 0 0"/>
      <mass value="0.005"/>
      <!--                <xacro:cylinder_inertia r="0.001" l="0.003" mass="${wheel_bar_mass}"/>-->
      <inertia ixx="0.000000026" ixy="0.0" ixz="0.0" iyy="0.000000026" iyz="0.0" izz="0.000000018"/>
    </inertial>
    <visual>
      <origin rpy="0 0 0" xyz="0 0 0"/>
      <geometry>
        <mesh filename="/home/ou/workspace/ros_ws/src/tricycle/meshes/bar.stl" scale="1.0 1.0 1.0"/>
      </geometry>
    </visual>
    <collision>
      <origin rpy="0 0 0" xyz="0 0 0"/>
      <geometry>
        <mesh filename="/home/ou/workspace/ros_ws/src/tricycle/meshes/bar.stl" scale="1.0 1.0 1.0"/>
      </geometry>
    </collision>
  </link>
  <joint name="wheel_2/bar_joint_11" type="continuous">
    <origin rpy="1.57079632679 0 5.75958653158" xyz="0.0173205080757 -0.01 0.01028"/>
    <axis xyz="0 0 1"/>
    <parent link="wheel_2"/>
    <child link="wheel_2/bar_11"/>
  </joint>
  <gazebo reference="wheel_2/bar_11">
    <mu1>0.5</mu1>
    <mu2>0.5</mu2>
    <material>Gazebo/Black</material>
    <gravity>true</gravity>
    <minDepth>0.0005 </minDepth>
  </gazebo>
  <gazebo laserRetro="0" maxContacts="100" reference="wheel_2" selfCollide="false"/>
  <transmission name="wheel_trans_2">
    <type>transmission_interface/SimpleTransmission</type>
    <joint name="base_wheel_2_joint">
      <hardwareInterface>hardware_interface/EffortJointInterface</hardwareInterface>
    </joint>
    <actuator name="wheel_act_2">
      <hardwareInterface>hardware_interface/EffortJointInterface</hardwareInterface>
      <mechanicalReduction>1</mechanicalReduction>
    </actuator>
  </transmission>
  <gazebo laserRetro="0" maxContacts="10" reference="base_link" selfCollide="false"/>
  <!--    <gazebo>-->
  <!--        <plugin name="gazebo_ros_control" filename="libgazebo_ros_control.so">-->
  <!--            <robotNamespace>/tricycle</robotNamespace>-->
  <!--            <robotSimType>gazebo_ros_control/DefaultRobotHWSim</robotSimType>-->
  <!--        </plugin>-->
  <!--    </gazebo>-->
</robot>
